{
 "cells": [
  {
   "cell_type": "markdown",
   "id": "5b3c2a43",
   "metadata": {},
   "source": [
    "## Implement the MNIST fashion dataset using a Recurrent Neural Network (RNN) in R, \n",
    "\n",
    "you can follow these steps:\n",
    "\n",
    "- Load the MNIST fashion dataset: The MNIST fashion dataset can be easily accessed through Keras in R.\n",
    "\n",
    "- Preprocess the data: Preprocess the data by normalizing it and reshaping it if needed.\n",
    "\n",
    "- Build the RNN model: Construct a recurrent neural network model using packages like TensorFlow or Keras.\n",
    "\n",
    "- Compile the model: Compile the model with appropriate loss function, optimizer, and metrics.\n",
    "\n",
    "- Train the model: Fit the model on the training data.\n",
    "\n",
    "- Evaluate the model: Evaluate the performance of the model on the test data"
   ]
  },
  {
   "cell_type": "code",
   "execution_count": 2,
   "id": "a75de91b",
   "metadata": {},
   "outputs": [
    {
     "name": "stdout",
     "output_type": "stream",
     "text": [
      "Epoch 1/10\n",
      "WARNING:tensorflow:Model was constructed with shape (None, None) for input KerasTensor(type_spec=TensorSpec(shape=(None, None), dtype=tf.float32, name='embedding_input'), name='embedding_input', description=\"created by layer 'embedding_input'\"), but it was called on an input with incompatible shape (128, 28, 28).\n"
     ]
    },
    {
     "ename": "ValueError",
     "evalue": "in user code:\n\n    File \"C:\\Users\\suyashi144893\\Anaconda3\\lib\\site-packages\\keras\\engine\\training.py\", line 1051, in train_function  *\n        return step_function(self, iterator)\n    File \"C:\\Users\\suyashi144893\\Anaconda3\\lib\\site-packages\\keras\\engine\\training.py\", line 1040, in step_function  **\n        outputs = model.distribute_strategy.run(run_step, args=(data,))\n    File \"C:\\Users\\suyashi144893\\Anaconda3\\lib\\site-packages\\keras\\engine\\training.py\", line 1030, in run_step  **\n        outputs = model.train_step(data)\n    File \"C:\\Users\\suyashi144893\\Anaconda3\\lib\\site-packages\\keras\\engine\\training.py\", line 889, in train_step\n        y_pred = self(x, training=True)\n    File \"C:\\Users\\suyashi144893\\Anaconda3\\lib\\site-packages\\keras\\utils\\traceback_utils.py\", line 67, in error_handler\n        raise e.with_traceback(filtered_tb) from None\n    File \"C:\\Users\\suyashi144893\\Anaconda3\\lib\\site-packages\\keras\\engine\\input_spec.py\", line 214, in assert_input_compatibility\n        raise ValueError(f'Input {input_index} of layer \"{layer_name}\" '\n\n    ValueError: Exception encountered when calling layer \"sequential\" (type Sequential).\n    \n    Input 0 of layer \"lstm\" is incompatible with the layer: expected ndim=3, found ndim=4. Full shape received: (128, 28, 28, 128)\n    \n    Call arguments received by layer \"sequential\" (type Sequential):\n      • inputs=tf.Tensor(shape=(128, 28, 28), dtype=float32)\n      • training=True\n      • mask=None\n",
     "output_type": "error",
     "traceback": [
      "\u001b[1;31m---------------------------------------------------------------------------\u001b[0m",
      "\u001b[1;31mValueError\u001b[0m                                Traceback (most recent call last)",
      "Input \u001b[1;32mIn [2]\u001b[0m, in \u001b[0;36m<cell line: 31>\u001b[1;34m()\u001b[0m\n\u001b[0;32m     24\u001b[0m model\u001b[38;5;241m.\u001b[39mcompile(\n\u001b[0;32m     25\u001b[0m     loss\u001b[38;5;241m=\u001b[39m\u001b[38;5;124m'\u001b[39m\u001b[38;5;124mcategorical_crossentropy\u001b[39m\u001b[38;5;124m'\u001b[39m,\n\u001b[0;32m     26\u001b[0m     optimizer\u001b[38;5;241m=\u001b[39m\u001b[38;5;124m'\u001b[39m\u001b[38;5;124madam\u001b[39m\u001b[38;5;124m'\u001b[39m,\n\u001b[0;32m     27\u001b[0m     metrics\u001b[38;5;241m=\u001b[39m[\u001b[38;5;124m'\u001b[39m\u001b[38;5;124maccuracy\u001b[39m\u001b[38;5;124m'\u001b[39m]\n\u001b[0;32m     28\u001b[0m )\n\u001b[0;32m     30\u001b[0m \u001b[38;5;66;03m# Train the model\u001b[39;00m\n\u001b[1;32m---> 31\u001b[0m history \u001b[38;5;241m=\u001b[39m \u001b[43mmodel\u001b[49m\u001b[38;5;241;43m.\u001b[39;49m\u001b[43mfit\u001b[49m\u001b[43m(\u001b[49m\n\u001b[0;32m     32\u001b[0m \u001b[43m    \u001b[49m\u001b[43mx_train\u001b[49m\u001b[43m,\u001b[49m\u001b[43m \u001b[49m\u001b[43my_train\u001b[49m\u001b[43m,\u001b[49m\n\u001b[0;32m     33\u001b[0m \u001b[43m    \u001b[49m\u001b[43mepochs\u001b[49m\u001b[38;5;241;43m=\u001b[39;49m\u001b[38;5;241;43m10\u001b[39;49m\u001b[43m,\u001b[49m\n\u001b[0;32m     34\u001b[0m \u001b[43m    \u001b[49m\u001b[43mbatch_size\u001b[49m\u001b[38;5;241;43m=\u001b[39;49m\u001b[38;5;241;43m128\u001b[39;49m\u001b[43m,\u001b[49m\n\u001b[0;32m     35\u001b[0m \u001b[43m    \u001b[49m\u001b[43mvalidation_split\u001b[49m\u001b[38;5;241;43m=\u001b[39;49m\u001b[38;5;241;43m0.2\u001b[39;49m\n\u001b[0;32m     36\u001b[0m \u001b[43m)\u001b[49m\n\u001b[0;32m     38\u001b[0m \u001b[38;5;66;03m# Evaluate the model\u001b[39;00m\n\u001b[0;32m     39\u001b[0m test_loss, test_accuracy \u001b[38;5;241m=\u001b[39m model\u001b[38;5;241m.\u001b[39mevaluate(x_test, y_test)\n",
      "File \u001b[1;32m~\\Anaconda3\\lib\\site-packages\\keras\\utils\\traceback_utils.py:67\u001b[0m, in \u001b[0;36mfilter_traceback.<locals>.error_handler\u001b[1;34m(*args, **kwargs)\u001b[0m\n\u001b[0;32m     65\u001b[0m \u001b[38;5;28;01mexcept\u001b[39;00m \u001b[38;5;167;01mException\u001b[39;00m \u001b[38;5;28;01mas\u001b[39;00m e:  \u001b[38;5;66;03m# pylint: disable=broad-except\u001b[39;00m\n\u001b[0;32m     66\u001b[0m   filtered_tb \u001b[38;5;241m=\u001b[39m _process_traceback_frames(e\u001b[38;5;241m.\u001b[39m__traceback__)\n\u001b[1;32m---> 67\u001b[0m   \u001b[38;5;28;01mraise\u001b[39;00m e\u001b[38;5;241m.\u001b[39mwith_traceback(filtered_tb) \u001b[38;5;28;01mfrom\u001b[39;00m \u001b[38;5;28mNone\u001b[39m\n\u001b[0;32m     68\u001b[0m \u001b[38;5;28;01mfinally\u001b[39;00m:\n\u001b[0;32m     69\u001b[0m   \u001b[38;5;28;01mdel\u001b[39;00m filtered_tb\n",
      "File \u001b[1;32mC:\\Users\\SUYASH~1\\AppData\\Local\\Temp\\1\\__autograph_generated_filemtj0tfhm.py:15\u001b[0m, in \u001b[0;36mouter_factory.<locals>.inner_factory.<locals>.tf__train_function\u001b[1;34m(iterator)\u001b[0m\n\u001b[0;32m     13\u001b[0m \u001b[38;5;28;01mtry\u001b[39;00m:\n\u001b[0;32m     14\u001b[0m     do_return \u001b[38;5;241m=\u001b[39m \u001b[38;5;28;01mTrue\u001b[39;00m\n\u001b[1;32m---> 15\u001b[0m     retval_ \u001b[38;5;241m=\u001b[39m ag__\u001b[38;5;241m.\u001b[39mconverted_call(ag__\u001b[38;5;241m.\u001b[39mld(step_function), (ag__\u001b[38;5;241m.\u001b[39mld(\u001b[38;5;28mself\u001b[39m), ag__\u001b[38;5;241m.\u001b[39mld(iterator)), \u001b[38;5;28;01mNone\u001b[39;00m, fscope)\n\u001b[0;32m     16\u001b[0m \u001b[38;5;28;01mexcept\u001b[39;00m:\n\u001b[0;32m     17\u001b[0m     do_return \u001b[38;5;241m=\u001b[39m \u001b[38;5;28;01mFalse\u001b[39;00m\n",
      "\u001b[1;31mValueError\u001b[0m: in user code:\n\n    File \"C:\\Users\\suyashi144893\\Anaconda3\\lib\\site-packages\\keras\\engine\\training.py\", line 1051, in train_function  *\n        return step_function(self, iterator)\n    File \"C:\\Users\\suyashi144893\\Anaconda3\\lib\\site-packages\\keras\\engine\\training.py\", line 1040, in step_function  **\n        outputs = model.distribute_strategy.run(run_step, args=(data,))\n    File \"C:\\Users\\suyashi144893\\Anaconda3\\lib\\site-packages\\keras\\engine\\training.py\", line 1030, in run_step  **\n        outputs = model.train_step(data)\n    File \"C:\\Users\\suyashi144893\\Anaconda3\\lib\\site-packages\\keras\\engine\\training.py\", line 889, in train_step\n        y_pred = self(x, training=True)\n    File \"C:\\Users\\suyashi144893\\Anaconda3\\lib\\site-packages\\keras\\utils\\traceback_utils.py\", line 67, in error_handler\n        raise e.with_traceback(filtered_tb) from None\n    File \"C:\\Users\\suyashi144893\\Anaconda3\\lib\\site-packages\\keras\\engine\\input_spec.py\", line 214, in assert_input_compatibility\n        raise ValueError(f'Input {input_index} of layer \"{layer_name}\" '\n\n    ValueError: Exception encountered when calling layer \"sequential\" (type Sequential).\n    \n    Input 0 of layer \"lstm\" is incompatible with the layer: expected ndim=3, found ndim=4. Full shape received: (128, 28, 28, 128)\n    \n    Call arguments received by layer \"sequential\" (type Sequential):\n      • inputs=tf.Tensor(shape=(128, 28, 28), dtype=float32)\n      • training=True\n      • mask=None\n"
     ]
    }
   ],
   "source": [
    "import tensorflow as tf\n",
    "from tensorflow.keras.datasets import fashion_mnist\n",
    "from tensorflow.keras.models import Sequential\n",
    "from tensorflow.keras.layers import LSTM, Dense, Embedding\n",
    "from tensorflow.keras.utils import to_categorical\n",
    "\n",
    "# Load MNIST fashion dataset\n",
    "(x_train, y_train), (x_test, y_test) = fashion_mnist.load_data()\n",
    "\n",
    "# Preprocess the data\n",
    "x_train = x_train / 255.0\n",
    "x_test = x_test / 255.0\n",
    "y_train = to_categorical(y_train)\n",
    "y_test = to_categorical(y_test)\n",
    "\n",
    "# Define RNN model\n",
    "model = Sequential([\n",
    "    Embedding(input_dim=784, output_dim=128),\n",
    "    LSTM(units=128),\n",
    "    Dense(units=10, activation='softmax')\n",
    "])\n",
    "\n",
    "# Compile the model\n",
    "model.compile(\n",
    "    loss='categorical_crossentropy',\n",
    "    optimizer='adam',\n",
    "    metrics=['accuracy']\n",
    ")\n",
    "\n",
    "# Train the model\n",
    "history = model.fit(\n",
    "    x_train, y_train,\n",
    "    epochs=10,\n",
    "    batch_size=128,\n",
    "    validation_split=0.2\n",
    ")\n",
    "\n",
    "# Evaluate the model\n",
    "test_loss, test_accuracy = model.evaluate(x_test, y_test)\n",
    "print(f'Test Loss: {test_loss}, Test Accuracy: {test_accuracy}')\n"
   ]
  },
  {
   "cell_type": "code",
   "execution_count": null,
   "id": "b9f80c70",
   "metadata": {},
   "outputs": [],
   "source": []
  }
 ],
 "metadata": {
  "kernelspec": {
   "display_name": "Python 3 (ipykernel)",
   "language": "python",
   "name": "python3"
  },
  "language_info": {
   "codemirror_mode": {
    "name": "ipython",
    "version": 3
   },
   "file_extension": ".py",
   "mimetype": "text/x-python",
   "name": "python",
   "nbconvert_exporter": "python",
   "pygments_lexer": "ipython3",
   "version": "3.9.12"
  }
 },
 "nbformat": 4,
 "nbformat_minor": 5
}
